{
 "cells": [
  {
   "cell_type": "code",
   "execution_count": 4,
   "id": "df3a833e-94b7-4106-a305-a9d8e5af7406",
   "metadata": {},
   "outputs": [],
   "source": [
    "import os\n",
    "from secret_key import openai_apikey"
   ]
  },
  {
   "cell_type": "raw",
   "id": "5a827a5b-2780-4c29-bebe-f1638a163ba1",
   "metadata": {},
   "source": [
    "os.environ['OPENAI_API_KEY'] = openai_apikey"
   ]
  },
  {
   "cell_type": "code",
   "execution_count": 5,
   "id": "39e42c99-86b6-4cfd-a647-4b051d048a64",
   "metadata": {},
   "outputs": [
    {
     "name": "stdout",
     "output_type": "stream",
     "text": [
      "sf-xxx\n"
     ]
    }
   ],
   "source": [
    "print(openai_apikey)"
   ]
  },
  {
   "cell_type": "code",
   "execution_count": 7,
   "id": "ca47a3c9-71ca-485c-80a9-192a80bb3232",
   "metadata": {},
   "outputs": [],
   "source": [
    "from langchain.llms import OpenAI"
   ]
  },
  {
   "cell_type": "code",
   "execution_count": 8,
   "id": "de3393fb-5489-4b57-9af3-3d2aee2938c3",
   "metadata": {},
   "outputs": [
    {
     "name": "stderr",
     "output_type": "stream",
     "text": [
      "/var/folders/vl/bw87vx9s3fldv4yvm6y43t8w0000gq/T/ipykernel_81293/2507204801.py:1: LangChainDeprecationWarning: The class `OpenAI` was deprecated in LangChain 0.0.10 and will be removed in 1.0. An updated version of the class exists in the :class:`~langchain-openai package and should be used instead. To use it run `pip install -U :class:`~langchain-openai` and import as `from :class:`~langchain_openai import OpenAI``.\n",
      "  llm = OpenAI(temp=0.6)\n",
      "/Users/amarkumar/ai-chat-bot-guide/.venv/lib/python3.10/site-packages/IPython/core/interactiveshell.py:3579: UserWarning: WARNING! temp is not default parameter.\n",
      "                temp was transferred to model_kwargs.\n",
      "                Please confirm that temp is what you intended.\n",
      "  exec(code_obj, self.user_global_ns, self.user_ns)\n"
     ]
    },
    {
     "ename": "ValidationError",
     "evalue": "1 validation error for OpenAI\n  Value error, Did not find openai_api_key, please add an environment variable `OPENAI_API_KEY` which contains it, or pass `openai_api_key` as a named parameter. [type=value_error, input_value={'model_kwargs': {'temp':...ne, 'http_client': None}, input_type=dict]\n    For further information visit https://errors.pydantic.dev/2.11/v/value_error",
     "output_type": "error",
     "traceback": [
      "\u001b[0;31m---------------------------------------------------------------------------\u001b[0m",
      "\u001b[0;31mValidationError\u001b[0m                           Traceback (most recent call last)",
      "Cell \u001b[0;32mIn[8], line 1\u001b[0m\n\u001b[0;32m----> 1\u001b[0m llm \u001b[38;5;241m=\u001b[39m \u001b[43mOpenAI\u001b[49m\u001b[43m(\u001b[49m\u001b[43mtemp\u001b[49m\u001b[38;5;241;43m=\u001b[39;49m\u001b[38;5;241;43m0.6\u001b[39;49m\u001b[43m)\u001b[49m\n",
      "File \u001b[0;32m~/ai-chat-bot-guide/.venv/lib/python3.10/site-packages/langchain_core/_api/deprecation.py:224\u001b[0m, in \u001b[0;36mdeprecated.<locals>.deprecate.<locals>.finalize.<locals>.warn_if_direct_instance\u001b[0;34m(self, *args, **kwargs)\u001b[0m\n\u001b[1;32m    222\u001b[0m     warned \u001b[38;5;241m=\u001b[39m \u001b[38;5;28;01mTrue\u001b[39;00m\n\u001b[1;32m    223\u001b[0m     emit_warning()\n\u001b[0;32m--> 224\u001b[0m \u001b[38;5;28;01mreturn\u001b[39;00m \u001b[43mwrapped\u001b[49m\u001b[43m(\u001b[49m\u001b[38;5;28;43mself\u001b[39;49m\u001b[43m,\u001b[49m\u001b[43m \u001b[49m\u001b[38;5;241;43m*\u001b[39;49m\u001b[43margs\u001b[49m\u001b[43m,\u001b[49m\u001b[43m \u001b[49m\u001b[38;5;241;43m*\u001b[39;49m\u001b[38;5;241;43m*\u001b[39;49m\u001b[43mkwargs\u001b[49m\u001b[43m)\u001b[49m\n",
      "File \u001b[0;32m~/ai-chat-bot-guide/.venv/lib/python3.10/site-packages/langchain_core/load/serializable.py:130\u001b[0m, in \u001b[0;36mSerializable.__init__\u001b[0;34m(self, *args, **kwargs)\u001b[0m\n\u001b[1;32m    128\u001b[0m \u001b[38;5;28;01mdef\u001b[39;00m\u001b[38;5;250m \u001b[39m\u001b[38;5;21m__init__\u001b[39m(\u001b[38;5;28mself\u001b[39m, \u001b[38;5;241m*\u001b[39margs: Any, \u001b[38;5;241m*\u001b[39m\u001b[38;5;241m*\u001b[39mkwargs: Any) \u001b[38;5;241m-\u001b[39m\u001b[38;5;241m>\u001b[39m \u001b[38;5;28;01mNone\u001b[39;00m:\n\u001b[1;32m    129\u001b[0m \u001b[38;5;250m    \u001b[39m\u001b[38;5;124;03m\"\"\"\"\"\"\u001b[39;00m  \u001b[38;5;66;03m# noqa: D419\u001b[39;00m\n\u001b[0;32m--> 130\u001b[0m     \u001b[38;5;28;43msuper\u001b[39;49m\u001b[43m(\u001b[49m\u001b[43m)\u001b[49m\u001b[38;5;241;43m.\u001b[39;49m\u001b[38;5;21;43m__init__\u001b[39;49m\u001b[43m(\u001b[49m\u001b[38;5;241;43m*\u001b[39;49m\u001b[43margs\u001b[49m\u001b[43m,\u001b[49m\u001b[43m \u001b[49m\u001b[38;5;241;43m*\u001b[39;49m\u001b[38;5;241;43m*\u001b[39;49m\u001b[43mkwargs\u001b[49m\u001b[43m)\u001b[49m\n",
      "File \u001b[0;32m~/ai-chat-bot-guide/.venv/lib/python3.10/site-packages/pydantic/main.py:253\u001b[0m, in \u001b[0;36mBaseModel.__init__\u001b[0;34m(self, **data)\u001b[0m\n\u001b[1;32m    251\u001b[0m \u001b[38;5;66;03m# `__tracebackhide__` tells pytest and some other tools to omit this function from tracebacks\u001b[39;00m\n\u001b[1;32m    252\u001b[0m __tracebackhide__ \u001b[38;5;241m=\u001b[39m \u001b[38;5;28;01mTrue\u001b[39;00m\n\u001b[0;32m--> 253\u001b[0m validated_self \u001b[38;5;241m=\u001b[39m \u001b[38;5;28;43mself\u001b[39;49m\u001b[38;5;241;43m.\u001b[39;49m\u001b[43m__pydantic_validator__\u001b[49m\u001b[38;5;241;43m.\u001b[39;49m\u001b[43mvalidate_python\u001b[49m\u001b[43m(\u001b[49m\u001b[43mdata\u001b[49m\u001b[43m,\u001b[49m\u001b[43m \u001b[49m\u001b[43mself_instance\u001b[49m\u001b[38;5;241;43m=\u001b[39;49m\u001b[38;5;28;43mself\u001b[39;49m\u001b[43m)\u001b[49m\n\u001b[1;32m    254\u001b[0m \u001b[38;5;28;01mif\u001b[39;00m \u001b[38;5;28mself\u001b[39m \u001b[38;5;129;01mis\u001b[39;00m \u001b[38;5;129;01mnot\u001b[39;00m validated_self:\n\u001b[1;32m    255\u001b[0m     warnings\u001b[38;5;241m.\u001b[39mwarn(\n\u001b[1;32m    256\u001b[0m         \u001b[38;5;124m'\u001b[39m\u001b[38;5;124mA custom validator is returning a value other than `self`.\u001b[39m\u001b[38;5;130;01m\\n\u001b[39;00m\u001b[38;5;124m'\u001b[39m\n\u001b[1;32m    257\u001b[0m         \u001b[38;5;124m\"\u001b[39m\u001b[38;5;124mReturning anything other than `self` from a top level model validator isn\u001b[39m\u001b[38;5;124m'\u001b[39m\u001b[38;5;124mt supported when validating via `__init__`.\u001b[39m\u001b[38;5;130;01m\\n\u001b[39;00m\u001b[38;5;124m\"\u001b[39m\n\u001b[1;32m    258\u001b[0m         \u001b[38;5;124m'\u001b[39m\u001b[38;5;124mSee the `model_validator` docs (https://docs.pydantic.dev/latest/concepts/validators/#model-validators) for more details.\u001b[39m\u001b[38;5;124m'\u001b[39m,\n\u001b[1;32m    259\u001b[0m         stacklevel\u001b[38;5;241m=\u001b[39m\u001b[38;5;241m2\u001b[39m,\n\u001b[1;32m    260\u001b[0m     )\n",
      "\u001b[0;31mValidationError\u001b[0m: 1 validation error for OpenAI\n  Value error, Did not find openai_api_key, please add an environment variable `OPENAI_API_KEY` which contains it, or pass `openai_api_key` as a named parameter. [type=value_error, input_value={'model_kwargs': {'temp':...ne, 'http_client': None}, input_type=dict]\n    For further information visit https://errors.pydantic.dev/2.11/v/value_error"
     ]
    }
   ],
   "source": [
    "llm = OpenAI(temp=0.6)"
   ]
  },
  {
   "cell_type": "code",
   "execution_count": null,
   "id": "035c8735-6089-43a4-804b-fe9459498c4c",
   "metadata": {},
   "outputs": [],
   "source": []
  }
 ],
 "metadata": {
  "kernelspec": {
   "display_name": "Python 3 (ipykernel)",
   "language": "python",
   "name": "python3"
  },
  "language_info": {
   "codemirror_mode": {
    "name": "ipython",
    "version": 3
   },
   "file_extension": ".py",
   "mimetype": "text/x-python",
   "name": "python",
   "nbconvert_exporter": "python",
   "pygments_lexer": "ipython3",
   "version": "3.10.11"
  }
 },
 "nbformat": 4,
 "nbformat_minor": 5
}
